<?xml version="1.0" encoding="utf-8"?>
<!-- This URDF was automatically created by SolidWorks to URDF Exporter! Originally created by Stephen Brawner (brawner@gmail.com) 
     Commit Version: 1.6.0-1-g15f4949  Build Version: 1.6.7594.29634
     For more information, please see http://wiki.ros.org/sw_urdf_exporter -->
<robot
  name="coloumn_description">
  <link
    name="base_link">
    <inertial>
      <origin
        xyz="0.083859 -0.5151 0.072059"
        rpy="0 0 0" />
      <mass
        value="2602.7" />
      <inertia
        ixx="2091.5"
        ixy="8.7862"
        ixz="-1.4249"
        iyy="1728.7"
        iyz="-61.531"
        izz="1376" />
    </inertial>
    <visual>
      <origin
        xyz="0 0 0"
        rpy="0 0 0" />
      <geometry>
        <mesh
          filename="package://coloumn_description/meshes/dae/base_link.dae" />
      </geometry>
      <material
        name="">
        <color
          rgba="0.79216 0.81961 0.93333 1" />
      </material>
    </visual>
    <collision>
      <origin
        xyz="0 0 0"
        rpy="0 0 0" />
      <geometry>
        <mesh
          filename="package://coloumn_description/meshes/stl/base_link.STL" />
      </geometry>
    </collision>
  </link>
  <link
    name="link_1">
    <inertial>
      <origin
        xyz="-4.59830585284842E-15 0.694881547901247 5.29069463240452E-15"
        rpy="0 0 0" />
      <mass
        value="245.900472770129" />
      <inertia
        ixx="164.332235084769"
        ixy="6.34468886049176E-13"
        ixz="-1.11022302462516E-15"
        iyy="4.33258951751966"
        iyz="-5.515823961466E-13"
        izz="164.332235084769" />
    </inertial>
    <visual>
      <origin
        xyz="0 0 0"
        rpy="${-radians(90)} 0 0" />
      <geometry>
        <mesh
          filename="package://coloumn_description/meshes/dae/link_1.dae" />
      </geometry>
      <material
        name="">
        <color
          rgba="0.792156862745098 0.819607843137255 0.933333333333333 1" />
      </material>
    </visual>
    <collision>
      <origin
        xyz="0 0 0"
        rpy="0 0 0" />
      <geometry>
        <mesh
          filename="package://coloumn_description/meshes/stl/link_1.STL" />
      </geometry>
    </collision>
  </link>
  <joint
    name="joint_0"
    type="continuous">
    <origin
      xyz="0 0 -0.052"
      rpy="${radians(90)} 0 0" />
    <parent
      link="base_link" />
    <child
      link="link_1" />
    <axis
      xyz="0 1 0" />
  </joint>
  <link
    name="link_2">
    <inertial>
      <origin
        xyz="-0.0772763117201542 -0.219325865578902 7.81202773802135E-10"
        rpy="0 0 0" />
      <mass
        value="746.442791588615" />
      <inertia
        ixx="242.047871612225"
        ixy="12.651235077018"
        ixz="1.13034789306354E-07"
        iyy="58.6789615463519"
        iyz="-1.91269995730714E-07"
        izz="279.753408215411" />
    </inertial>
    <visual>
      <origin
        xyz="0 0 0"
        rpy="${-radians(90)} 0 0" />
      <geometry>
        <mesh
          filename="package://coloumn_description/meshes/dae/link_2.dae" />
      </geometry>
      <material
        name="">
        <color
          rgba="0.792156862745098 0.819607843137255 0.933333333333333 1" />
      </material>
    </visual>
    <collision>
      <origin
        xyz="0 0 0"
        rpy="0 0 0" />
      <geometry>
        <mesh
          filename="package://coloumn_description/meshes/stl/link_2.STL" />
      </geometry>
    </collision>
  </link>
  <joint
    name="joint_1"
    type="prismatic">
    <origin
      xyz="0 2.541 0"
      rpy="0 0 0" />
    <parent
      link="link_1" />
    <child
      link="link_2" />
    <axis
      xyz="0 1 0" />
    <limit
      lower="0"
      upper="1.8"
      effort="0"
      velocity="0" />
  </joint>
  <link
    name="link_3">
    <inertial>
      <origin
        xyz="9.75044697759664E-15 4.44089209850063E-16 -0.388572638007358"
        rpy="0 0 0" />
      <mass
        value="53.0427720770906" />
      <inertia
        ixx="4.7128315654114"
        ixy="1.47277784459852E-15"
        ixz="9.60564093543947E-14"
        iyy="4.74286563597603"
        iyz="1.55506089182359E-16"
        izz="0.571997737496323" />
    </inertial>
    <visual>
      <origin
        xyz="0 0 0"
        rpy="${-radians(180)} 0 0" />
      <geometry>
        <mesh
          filename="package://coloumn_description/meshes/dae/link_3.dae" />
      </geometry>
      <material
        name="">
        <color
          rgba="0.792156862745098 0.819607843137255 0.933333333333333 1" />
      </material>
    </visual>
    <collision>
      <origin
        xyz="0 0 0"
        rpy="0 0 0" />
      <geometry>
        <mesh
          filename="package://coloumn_description/meshes/stl/link_3.STL" />
      </geometry>
    </collision>
  </link>
  <joint
    name="joint_2"
    type="prismatic">
    <origin
      xyz="-0.24211 0 0"
      rpy="0 ${radians(90)} 0" />
    <parent
      link="link_2" />
    <child
      link="link_3" />
    <axis
      xyz="0 0 -1" />
    <limit
      lower="0"
      upper="0.6"
      effort="0"
      velocity="0" />
  </joint>
  <link
    name="link_4">
    <inertial>
      <origin
        xyz="-0.000999999999999709 -0.380155199499237 -2.66453525910038E-15"
        rpy="0 0 0" />
      <mass
        value="148.758636421247" />
      <inertia
        ixx="33.2544832322811"
        ixy="1.94116641163977E-14"
        ixz="5.82867087928207E-16"
        iyy="0.617641615237808"
        iyz="-2.00622155742619E-13"
        izz="33.2290109937646" />
    </inertial>
    <visual>
      <origin
        xyz="0 0 0"
        rpy="0 0 0" />
      <geometry>
        <mesh
          filename="package://coloumn_description/meshes/dae/link_4.dae" />
      </geometry>
      <material
        name="">
        <color
          rgba="0.792156862745098 0.819607843137255 0.933333333333333 1" />
      </material>
    </visual>
    <collision>
      <origin
        xyz="0 0 0"
        rpy="0 0 0" />
      <geometry>
        <mesh
          filename="package://coloumn_description/meshes/stl/link_4.STL" />
      </geometry>
    </collision>
  </link>
  <joint
    name="joint_3"
    type="revolute">
    <origin
      xyz="0 0 -1.0315"
      rpy="2.81 0 ${-radians(180)}" />
    <parent
      link="link_3" />
    <child
      link="link_4" />
    <axis
      xyz="1 0 0" />
    <limit
      lower="0"
      upper="${radians(38)}"
      effort="0"
      velocity="0" />
  </joint>
  <link
    name="tool"/>
  <joint
    name="joint_4"
    type="fixed">
    <origin
      xyz="0 -1.6145 0"
      rpy="${radians(90)} ${-radians(90)} 0" />
    <parent
      link="link_4" />
    <child
      link="tool" />
    <axis
      xyz="0 0 1" />
  </joint>
</robot>
